Workbook

Sheet All_Photoquad_codes_PC_NoSTR
A1: PARENT_CODE | B1: PARENT_DESC | C1: PARENT RANK | D1: CHILD_CODE | E1: CHILD_DESC | F1: CHILD_RANK | G1: FLAG_LOOP
A2: OBJ | B2: Object | C2: TX | D2: BIOTA | E2: Biological Code | F2: T0 | G2: ROOT
A3: OBJ | B3: Object | C3: TX | D3: OFFSURVEY | E3: NonTarget | F3: T0 | G3: ROOT
A4: OBJ | B4: Object | C4: TX | D4: SUBS | E4: Substrate | F4: T0 | G4: ROOT
A5: BIOTA | B5: Biological Code | C5: T0 | D5: CCA | E5: Coralline Alga | F5: T1 | G5: BIOTREE
A6: BIOTA | B6: Biological Code | C6: T0 | D6: CORAL | E6: Coral | F6: T1 | G6: BIOTREE
A7: BIOTA | B7: Biological Code | C7: T0 | D7: I | E7: Sessile Invertebrate | F7: T1 | G7: BIOTREE
A8: BIOTA | B8: Biological Code | C8: T0 | D8: MA | E8: Macroalga | F8: T1 | G8: BIOTREE
A9: BIOTA | B9: Biological Code | C9: T0 | D9: MF | E9: Mobile Fauna | F9: T1 | G9: BIOTREE
A10: BIOTA | B10: Biological Code | C10: T0 | D10: TURF | E10: Turf Alga | F10: T1 | G10: BIOTREE
A11: OFFSURVEY | B11: NonTarget | C11: T0 | D11: TW | E11: Tape and wand | F11: T1 | G11: OFFTREE
A12: OFFSURVEY | B12: NonTarget | C12: T0 | D12: UC | E12: Unclassified | F12: T1 | G12: OFFTREE
... A80: UC | B80: Unclassified | C80: T1 | D80: UNK | E80: Unclassified/Unknown | F80: T2 | G80: OFFTREE
A81: =_xlfn.XLOOKUP($D81,All_Photoquad_codes_HeirarchyTr!$G$2:$G$111,All_Photoquad_codes_HeirarchyTr!E$2:E$111) -> ACSP | B81: =_xlfn.XLOOKUP($D81,All_Photoquad_codes_HeirarchyTr!$G$2:$G$111,All_Photoquad_codes_HeirarchyTr!F$2:F$111) -> Acropora sp | C81: T2 | D81: ACBR | E81: Acropora branching | F81: T3 | G81: BIOLOOP_TAX
A82: =_xlfn.XLOOKUP($D82,All_Photoquad_codes_HeirarchyTr!$G$2:$G$111,All_Photoquad_codes_HeirarchyTr!E$2:E$111) -> ACSP | B82: =_xlfn.XLOOKUP($D82,All_Photoquad_codes_HeirarchyTr!$G$2:$G$111,All_Photoquad_codes_HeirarchyTr!F$2:F$111) -> Acropora sp | C82: T2 | D82: ACTA | E82: Acropora tabulate | F82: T3 | G82: BIOLOOP_TAX
A83: EMA | B83: Encrusting macroalga | C83: T2 | D83: PESP | E83: Peyssonnelia sp | F83: T2b | G83: BIOTREE
A84: =_xlfn.XLOOKUP($D84,All_Photoquad_codes_HeirarchyTr!$G$2:$G$111,All_Photoquad_codes_HeirarchyTr!E$2:E$111) -> MOSP | B84: =_xlfn.XLOOKUP($D84,All_Photoquad_codes_HeirarchyTr!$G$2:$G$111,All_Photoquad_codes_HeirarchyTr!F$2:F$111) -> Montipora sp | C84: T2 | D84: MOBR | E84: Montipora branching | F84: T3 | G84: BIOLOOP_TAX
A85: =_xlfn.XLOOKUP($D85,All_Photoquad_codes_HeirarchyTr!$G$2:$G$111,All_Photoquad_codes_HeirarchyTr!E$2:E$111) -> MOSP | B85: =_xlfn.XLOOKUP($D85,All_Photoquad_codes_HeirarchyTr!$G$2:$G$111,All_Photoquad_codes_HeirarchyTr!F$2:F$111) -> Montipora sp | C85: T2 | D85: MOEN | E85: Montipora encrusting | F85: T3 | G85: BIOLOOP_TAX
A86: =_xlfn.XLOOKUP($D86,All_Photoquad_codes_HeirarchyTr!$G$2:$G$111,All_Photoquad_codes_HeirarchyTr!E$2:E$111) -> MOSP | B86: =_xlfn.XLOOKUP($D86,All_Photoquad_codes_HeirarchyTr!$G$2:$G$111,All_Photoquad_codes_HeirarchyTr!F$2:F$111) -> Montipora sp | C86: T2 | D86: MOFO | E86: Montipora foliose | F86: T3 | G86: BIOLOOP_TAX
A87: =_xlfn.XLOOKUP($D87,All_Photoquad_codes_HeirarchyTr!$G$2:$G$111,All_Photoquad_codes_HeirarchyTr!E$2:E$111) -> MOSP | B87: =_xlfn.XLOOKUP($D87,All_Photoquad_codes_HeirarchyTr!$G$2:$G$111,All_Photoquad_codes_HeirarchyTr!F$2:F$111) -> Montipora sp | C87: T2 | D87: MONE | E87: Montipora sp non-encrusting | F87: T3 | G87: BIOLOOP_TAX
A88: NS | B88: Non-scleractinian hard coral | C88: T2 | D88: HCOE | E88: Heliopora sp | F88: T2b | G88: BIOTREE
A89: NS | B89: Non-scleractinian hard coral | C89: T2 | D89: HYCO | E89: Hydrocoral | F89: T2b | G89: BIOTREE
A90: =_xlfn.XLOOKUP($D90,All_Photoquad_codes_HeirarchyTr!$G$2:$G$111,All_Photoquad_codes_HeirarchyTr!E$2:E$111) -> PAVS | B90: =_xlfn.XLOOKUP($D90,All_Photoquad_codes_HeirarchyTr!$G$2:$G$111,All_Photoquad_codes_HeirarchyTr!F$2:F$111) -> Pavona sp | C90: T2 | D90: PAEN | E90: Pavona encrusting | F90: T3 | G90: BIOLOOP_TAX
A91: =_xlfn.XLOOKUP($D91,All_Photoquad_codes_HeirarchyTr!$G$2:$G$111,All_Photoquad_codes_HeirarchyTr!E$2:E$111) -> PAVS | B91: =_xlfn.XLOOKUP($D91,All_Photoquad_codes_HeirarchyTr!$G$2:$G$111,All_Photoquad_codes_HeirarchyTr!F$2:F$111) -> Pavona sp | C91: T2 | D91: PAFO | E91: Pavona foliose | F91: T3 | G91: BIOLOOP_TAX
A92: =_xlfn.XLOOKUP($D92,All_Photoquad_codes_HeirarchyTr!$G$2:$G$111,All_Photoquad_codes_HeirarchyTr!E$2:E$111) -> PAVS | B92: =_xlfn.XLOOKUP($D92,All_Photoquad_codes_HeirarchyTr!$G$2:$G$111,All_Photoquad_codes_HeirarchyTr!F$2:F$111) -> Pavona sp | C92: T2 | D92: PAMA | E92: Pavona massive | F92: T3 | G92: BIOLOOP_TAX
A93: =_xlfn.XLOOKUP($D93,All_Photoquad_codes_HeirarchyTr!$G$2:$G$111,All_Photoquad_codes_HeirarchyTr!E$2:E$111) -> POSP | B93: =_xlfn.XLOOKUP($D93,All_Photoquad_codes_HeirarchyTr!$G$2:$G$111,All_Photoquad_codes_HeirarchyTr!F$2:F$111) -> Porites sp | C93: T2 | D93: POBR | E93: Porites branching | F93: T3 | G93: BIOLOOP_TAX
A94: =_xlfn.XLOOKUP($D94,All_Photoquad_codes_HeirarchyTr!$G$2:$G$111,All_Photoquad_codes_HeirarchyTr!E$2:E$111) -> POSP | B94: =_xlfn.XLOOKUP($D94,All_Photoquad_codes_HeirarchyTr!$G$2:$G$111,All_Photoquad_codes_HeirarchyTr!F$2:F$111) -> Porites sp | C94: T2 | D94: POEN | E94: Porites encrusting | F94: T3 | G94: BIOLOOP_TAX
A95: =_xlfn.XLOOKUP($D95,All_Photoquad_codes_HeirarchyTr!$G$2:$G$111,All_Photoquad_codes_HeirarchyTr!E$2:E$111) -> POSP | B95: =_xlfn.XLOOKUP($D95,All_Photoquad_codes_HeirarchyTr!$G$2:$G$111,All_Photoquad_codes_HeirarchyTr!F$2:F$111) -> Porites sp | C95: T2 | D95: POFO | E95: Porites foliose | F95: T3 | G95: BIOLOOP_TAX
A96: =_xlfn.XLOOKUP($D96,All_Photoquad_codes_HeirarchyTr!$G$2:$G$111,All_Photoquad_codes_HeirarchyTr!E$2:E$111) -> POSP | B96: =_xlfn.XLOOKUP($D96,All_Photoquad_codes_HeirarchyTr!$G$2:$G$111,All_Photoquad_codes_HeirarchyTr!F$2:F$111) -> Porites sp | C96: T2 | D96: POMA | E96: Porites massive | F96: T3 | G96: BIOLOOP_TAX
A97: =_xlfn.XLOOKUP($D97,All_Photoquad_codes_HeirarchyTr!$G$2:$G$111,All_Photoquad_codes_HeirarchyTr!E$2:E$111) -> POSP | B97: =_xlfn.XLOOKUP($D97,All_Photoquad_codes_HeirarchyTr!$G$2:$G$111,All_Photoquad_codes_HeirarchyTr!F$2:F$111) -> Porites sp | C97: T2 | D97: PONM | E97: Porites sp non-massive | F97: T3 | G97: BIOLOOP_TAX
A98: UPMA | B98: Upright macroalga | C98: T2 | D98: ASPP | E98: Asparagopsis sp | F98: T2b | G98: BIOTREE
A99: UPMA | B99: Upright macroalga | C99: T2 | D99: BGMA | E99: Blue-green macroalga | F99: T2b | G99: BIOTREE
A100: UPMA | B100: Upright macroalga | C100: T2 | D100: BRMA | E100: Brown macroalgae | F100: T2b | G100: BIOTREE
A101: UPMA | B101: Upright macroalga | C101: T2 | D101: DICT | E101: Dictyosphaeria sp | F101: T2b | G101: BIOTREE
A102: UPMA | B102: Upright macroalga | C102: T2 | D102: GRMA | E102: Green macroalga | F102: T2b | G102: BIOTREE
A103: UPMA | B103: Upright macroalga | C103: T2 | D103: HALI | E103: Halimeda sp | F103: T2b | G103: BIOTREE
A104: UPMA | B104: Upright macroalga | C104: T2 | D104: LOBO | E104: Lobophora sp | F104: T2b | G104: BIOTREE
A105: UPMA | B105: Upright macroalga | C105: T2 | D105: MICR | E105: Microdictyon sp | F105: T2b | G105: BIOTREE
A106: UPMA | B106: Upright macroalga | C106: T2 | D106: PADI | E106: Padina sp | F106: T2b | G106: BIOTREE
A107: UPMA | B107: Upright macroalga | C107: T2 | D107: RDMA | E107: Red macroalgae | F107: T2b | G107: BIOTREE
...

Sheet All_Photoquad_codes_ParentChild
A1: PARENT_CODE | B1: PARENT_DESC | C1: PARENT RANK | D1: CHILD_CODE | E1: CHILD_DESC | F1: CHILD_RANK | G1: FLAG_LOOP
A2: OBJ | B2: Object | C2: TX | D2: BIOTA | E2: Biological Code | F2: T0 | G2: ROOT
A3: OBJ | B3: Object | C3: TX | D3: OFFSURVEY | E3: NonTarget | F3: T0 | G3: ROOT
A4: OBJ | B4: Object | C4: TX | D4: SUBS | E4: Substrate | F4: T0 | G4: ROOT
A5: BIOTA | B5: Biological Code | C5: T0 | D5: CCA | E5: Coralline Alga | F5: T1 | G5: BIOTREE
A6: BIOTA | B6: Biological Code | C6: T0 | D6: CORAL | E6: Coral | F6: T1 | G6: BIOTREE
A7: BIOTA | B7: Biological Code | C7: T0 | D7: I | E7: Sessile Invertebrate | F7: T1 | G7: BIOTREE
A8: BIOTA | B8: Biological Code | C8: T0 | D8: MA | E8: Macroalga | F8: T1 | G8: BIOTREE
A9: BIOTA | B9: Biological Code | C9: T0 | D9: MF | E9: Mobile Fauna | F9: T1 | G9: BIOTREE
A10: BIOTA | B10: Biological Code | C10: T0 | D10: TURF | E10: Turf Alga | F10: T1 | G10: BIOTREE
A11: OFFSURVEY | B11: NonTarget | C11: T0 | D11: TW | E11: Tape and wand | F11: T1 | G11: OFFTREE
A12: OFFSURVEY | B12: NonTarget | C12: T0 | D12: UC | E12: Unclassified | F12: T1 | G12: OFFTREE
... A87: UC | B87: Unclassified | C87: T1 | D87: UNK | E87: Unclassified/Unknown | F87: T2 | G87: OFFTREE
A88: =_xlfn.XLOOKUP($D88,All_Photoquad_codes_HeirarchyTr!$G$2:$G$111,All_Photoquad_codes_HeirarchyTr!E$2:E$111) -> ACSP | B88: =_xlfn.XLOOKUP($D88,All_Photoquad_codes_HeirarchyTr!$G$2:$G$111,All_Photoquad_codes_HeirarchyTr!F$2:F$111) -> Acropora sp | C88: T2 | D88: ACBR | E88: Acropora branching | F88: T3 | G88: BIOLOOP_TAX
A89: =_xlfn.XLOOKUP($D89,All_Photoquad_codes_HeirarchyTr!$G$2:$G$111,All_Photoquad_codes_HeirarchyTr!E$2:E$111) -> ACSP | B89: =_xlfn.XLOOKUP($D89,All_Photoquad_codes_HeirarchyTr!$G$2:$G$111,All_Photoquad_codes_HeirarchyTr!F$2:F$111) -> Acropora sp | C89: T2 | D89: ACTA | E89: Acropora tabulate | F89: T3 | G89: BIOLOOP_TAX
A90: =_xlfn.XLOOKUP($D90,All_Photoquad_codes_HeirarchyTr!$G$2:$G$111,All_Photoquad_codes_HeirarchyTr!C$2:C$111) -> BR | B90: =_xlfn.XLOOKUP($D90,All_Photoquad_codes_HeirarchyTr!$G$2:$G$111,All_Photoquad_codes_HeirarchyTr!D$2:D$111) -> Branching hard coral | C90: T2 | D90: ACBR | E90: Acropora branching | F90: T3 | G90: BIOLOOP_STR
A91: =_xlfn.XLOOKUP($D91,All_Photoquad_codes_HeirarchyTr!$G$2:$G$111,All_Photoquad_codes_HeirarchyTr!C$2:C$111) -> BR | B91: =_xlfn.XLOOKUP($D91,All_Photoquad_codes_HeirarchyTr!$G$2:$G$111,All_Photoquad_codes_HeirarchyTr!D$2:D$111) -> Branching hard coral | C91: T2 | D91: MOBR | E91: Montipora branching | F91: T3 | G91: BIOLOOP_STR
A92: =_xlfn.XLOOKUP($D92,All_Photoquad_codes_HeirarchyTr!$G$2:$G$111,All_Photoquad_codes_HeirarchyTr!C$2:C$111) -> BR | B92: =_xlfn.XLOOKUP($D92,All_Photoquad_codes_HeirarchyTr!$G$2:$G$111,All_Photoquad_codes_HeirarchyTr!D$2:D$111) -> Branching hard coral | C92: T2 | D92: POBR | E92: Porites branching | F92: T3 | G92: BIOLOOP_STR
A93: =_xlfn.XLOOKUP($D93,All_Photoquad_codes_HeirarchyTr!$G$2:$G$111,All_Photoquad_codes_HeirarchyTr!C$2:C$111) -> CORAL | B93: =_xlfn.XLOOKUP($D93,All_Photoquad_codes_HeirarchyTr!$G$2:$G$111,All_Photoquad_codes_HeirarchyTr!D$2:D$111) -> Hard coral | C93: T2 | D93: MONE | E93: Montipora sp non-encrusting | F93: T3 | G93: BIOLOOP_STR
A94: =_xlfn.XLOOKUP($D94,All_Photoquad_codes_HeirarchyTr!$G$2:$G$111,All_Photoquad_codes_HeirarchyTr!C$2:C$111) -> CORAL | B94: =_xlfn.XLOOKUP($D94,All_Photoquad_codes_HeirarchyTr!$G$2:$G$111,All_Photoquad_codes_HeirarchyTr!D$2:D$111) -> Hard coral | C94: T2 | D94: PONM | E94: Porites sp non-massive | F94: T3 | G94: BIOLOOP_STR
A95: EMA | B95: Encrusting macroalga | C95: T2 | D95: PESP | E95: Peyssonnelia sp | F95: T2b | G95: BIOTREE
A96: =_xlfn.XLOOKUP($D96,All_Photoquad_codes_HeirarchyTr!$G$2:$G$111,All_Photoquad_codes_HeirarchyTr!C$2:C$111) -> ENC | B96: =_xlfn.XLOOKUP($D96,All_Photoquad_codes_HeirarchyTr!$G$2:$G$111,All_Photoquad_codes_HeirarchyTr!D$2:D$111) -> Encrusting hard coral | C96: T2 | D96: MOEN | E96: Montipora encrusting | F96: T3 | G96: BIOLOOP_STR
A97: =_xlfn.XLOOKUP($D97,All_Photoquad_codes_HeirarchyTr!$G$2:$G$111,All_Photoquad_codes_HeirarchyTr!C$2:C$111) -> ENC | B97: =_xlfn.XLOOKUP($D97,All_Photoquad_codes_HeirarchyTr!$G$2:$G$111,All_Photoquad_codes_HeirarchyTr!D$2:D$111) -> Encrusting hard coral | C97: T2 | D97: PAEN | E97: Pavona encrusting | F97: T3 | G97: BIOLOOP_STR
A98: =_xlfn.XLOOKUP($D98,All_Photoquad_codes_HeirarchyTr!$G$2:$G$111,All_Photoquad_codes_HeirarchyTr!C$2:C$111) -> ENC | B98: =_xlfn.XLOOKUP($D98,All_Photoquad_codes_HeirarchyTr!$G$2:$G$111,All_Photoquad_codes_HeirarchyTr!D$2:D$111) -> Encrusting hard coral | C98: T2 | D98: POEN | E98: Porites encrusting | F98: T3 | G98: BIOLOOP_STR
A99: =_xlfn.XLOOKUP($D99,All_Photoquad_codes_HeirarchyTr!$G$2:$G$111,All_Photoquad_codes_HeirarchyTr!C$2:C$111) -> FOL | B99: =_xlfn.XLOOKUP($D99,All_Photoquad_codes_HeirarchyTr!$G$2:$G$111,All_Photoquad_codes_HeirarchyTr!D$2:D$111) -> Foliose hard coral | C99: T2 | D99: MOFO | E99: Montipora foliose | F99: T3 | G99: BIOLOOP_STR
A100: =_xlfn.XLOOKUP($D100,All_Photoquad_codes_HeirarchyTr!$G$2:$G$111,All_Photoquad_codes_HeirarchyTr!C$2:C$111) -> FOL | B100: =_xlfn.XLOOKUP($D100,All_Photoquad_codes_HeirarchyTr!$G$2:$G$111,All_Photoquad_codes_HeirarchyTr!D$2:D$111) -> Foliose hard coral | C100: T2 | D100: PAFO | E100: Pavona foliose | F100: T3 | G100: BIOLOOP_STR
A101: =_xlfn.XLOOKUP($D101,All_Photoquad_codes_HeirarchyTr!$G$2:$G$111,All_Photoquad_codes_HeirarchyTr!C$2:C$111) -> FOL | B101: =_xlfn.XLOOKUP($D101,All_Photoquad_codes_HeirarchyTr!$G$2:$G$111,All_Photoquad_codes_HeirarchyTr!D$2:D$111) -> Foliose hard coral | C101: T2 | D101: POFO | E101: Porites foliose | F101: T3 | G101: BIOLOOP_STR
A102: =_xlfn.XLOOKUP($D102,All_Photoquad_codes_HeirarchyTr!$G$2:$G$111,All_Photoquad_codes_HeirarchyTr!C$2:C$111) -> MASS | B102: =_xlfn.XLOOKUP($D102,All_Photoquad_codes_HeirarchyTr!$G$2:$G$111,All_Photoquad_codes_HeirarchyTr!D$2:D$111) -> Massive hard coral | C102: T2 | D102: PAMA | E102: Pavona massive | F102: T3 | G102: BIOLOOP_STR
A103: =_xlfn.XLOOKUP($D103,All_Photoquad_codes_HeirarchyTr!$G$2:$G$111,All_Photoquad_codes_HeirarchyTr!C$2:C$111) -> MASS | B103: =_xlfn.XLOOKUP($D103,All_Photoquad_codes_HeirarchyTr!$G$2:$G$111,All_Photoquad_codes_HeirarchyTr!D$2:D$111) -> Massive hard coral | C103: T2 | D103: POMA | E103: Porites massive | F103: T3 | G103: BIOLOOP_STR
A104: =_xlfn.XLOOKUP($D104,All_Photoquad_codes_HeirarchyTr!$G$2:$G$111,All_Photoquad_codes_HeirarchyTr!E$2:E$111) -> MOSP | B104: =_xlfn.XLOOKUP($D104,All_Photoquad_codes_HeirarchyTr!$G$2:$G$111,All_Photoquad_codes_HeirarchyTr!F$2:F$111) -> Montipora sp | C104: T2 | D104: MOBR | E104: Montipora branching | F104: T3 | G104: BIOLOOP_TAX
A105: =_xlfn.XLOOKUP($D105,All_Photoquad_codes_HeirarchyTr!$G$2:$G$111,All_Photoquad_codes_HeirarchyTr!E$2:E$111) -> MOSP | B105: =_xlfn.XLOOKUP($D105,All_Photoquad_codes_HeirarchyTr!$G$2:$G$111,All_Photoquad_codes_HeirarchyTr!F$2:F$111) -> Montipora sp | C105: T2 | D105: MOEN | E105: Montipora encrusting | F105: T3 | G105: BIOLOOP_TAX
A106: =_xlfn.XLOOKUP($D106,All_Photoquad_codes_HeirarchyTr!$G$2:$G$111,All_Photoquad_codes_HeirarchyTr!E$2:E$111) -> MOSP | B106: =_xlfn.XLOOKUP($D106,All_Photoquad_codes_HeirarchyTr!$G$2:$G$111,All_Photoquad_codes_HeirarchyTr!F$2:F$111) -> Montipora sp | C106: T2 | D106: MOFO | E106: Montipora foliose | F106: T3 | G106: BIOLOOP_TAX
A107: =_xlfn.XLOOKUP($D107,All_Photoquad_codes_HeirarchyTr!$G$2:$G$111,All_Photoquad_codes_HeirarchyTr!E$2:E$111) -> MOSP | B107: =_xlfn.XLOOKUP($D107,All_Photoquad_codes_HeirarchyTr!$G$2:$G$111,All_Photoquad_codes_HeirarchyTr!F$2:F$111) -> Montipora sp | C107: T2 | D107: MONE | E107: Montipora sp non-encrusting | F107: T3 | G107: BIOLOOP_TAX
A108: NS | B108: Non-scleractinian hard coral | C108: T2 | D108: HCOE | E108: Heliopora sp | F108: T2b | G108: BIOTREE
A109: NS | B109: Non-scleractinian hard coral | C109: T2 | D109: HYCO | E109: Hydrocoral | F109: T2b | G109: BIOTREE
A110: =_xlfn.XLOOKUP($D110,All_Photoquad_codes_HeirarchyTr!$G$2:$G$111,All_Photoquad_codes_HeirarchyTr!E$2:E$111) -> PAVS | B110: =_xlfn.XLOOKUP($D110,All_Photoquad_codes_HeirarchyTr!$G$2:$G$111,All_Photoquad_codes_HeirarchyTr!F$2:F$111) -> Pavona sp | C110: T2 | D110: PAEN | E110: Pavona encrusting | F110: T3 | G110: BIOLOOP_TAX
A111: =_xlfn.XLOOKUP($D111,All_Photoquad_codes_HeirarchyTr!$G$2:$G$111,All_Photoquad_codes_HeirarchyTr!E$2:E$111) -> PAVS | B111: =_xlfn.XLOOKUP($D111,All_Photoquad_codes_HeirarchyTr!$G$2:$G$111,All_Photoquad_codes_HeirarchyTr!F$2:F$111) -> Pavona sp | C111: T2 | D111: PAFO | E111: Pavona foliose | F111: T3 | G111: BIOLOOP_TAX
A112: =_xlfn.XLOOKUP($D112,All_Photoquad_codes_HeirarchyTr!$G$2:$G$111,All_Photoquad_codes_HeirarchyTr!E$2:E$111) -> PAVS | B112: =_xlfn.XLOOKUP($D112,All_Photoquad_codes_HeirarchyTr!$G$2:$G$111,All_Photoquad_codes_HeirarchyTr!F$2:F$111) -> Pavona sp | C112: T2 | D112: PAMA | E112: Pavona massive | F112: T3 | G112: BIOLOOP_TAX
A113: =_xlfn.XLOOKUP($D113,All_Photoquad_codes_HeirarchyTr!$G$2:$G$111,All_Photoquad_codes_HeirarchyTr!E$2:E$111) -> POSP | B113: =_xlfn.XLOOKUP($D113,All_Photoquad_codes_HeirarchyTr!$G$2:$G$111,All_Photoquad_codes_HeirarchyTr!F$2:F$111) -> Porites sp | C113: T2 | D113: POBR | E113: Porites branching | F113: T3 | G113: BIOLOOP_TAX
A114: =_xlfn.XLOOKUP($D114,All_Photoquad_codes_HeirarchyTr!$G$2:$G$111,All_Photoquad_codes_HeirarchyTr!E$2:E$111) -> POSP | B114: =_xlfn.XLOOKUP($D114,All_Photoquad_codes_HeirarchyTr!$G$2:$G$111,All_Photoquad_codes_HeirarchyTr!F$2:F$111) -> Porites sp | C114: T2 | D114: POEN | E114: Porites encrusting | F114: T3 | G114: BIOLOOP_TAX
...

Sheet All_Photoquad_codes_HeirarchyTr
A1: TIER_1 | B1: T1_DESC | C1: TIER_2 | D1: T2_DESC | E1: TIER_2b | F1: T2b_DESC | G1: TIER_3 | H1: T3_DESC | I1: Cnet_SHORT_CODE | J1: CODE
A2: CCA | B2: Coralline Alga | C2: CCAH | D2: CCA growing on hard substrate | E2: CCAH | F2: CCA growing on hard substrate | G2: CCAH | H2: CCA growing on hard substrate | I2: *CCAH | J2: CCAH
A3: CCA | B3: Coralline Alga | C3: CCAR | D3: CCA growing on rubble | E3: CCAR | F3: CCA growing on rubble | G3: CCAR | H3: CCA growing on rubble | I3: *CCAR | J3: CCAR
A4: CORAL | B4: Coral | C4: BR | D4: Branching hard coral | E4: ACSP | F4: Acropora sp | G4: ACBR | H4: Acropora branching | I4: *ACBR | J4: ACBR
A5: CORAL | B5: Coral | C5: BR | D5: Branching hard coral | E5: BR | F5: Branching hard coral | G5: BR | H5: Branching hard coral | I5: *BR | J5: BR
A6: CORAL | B6: Coral | C6: BR | D6: Branching hard coral | E6: EUSP | F6: Euphyllia sp | G6: EUSP | H6: Euphyllia sp | I6: *EUSP | J6: EUSP
A7: CORAL | B7: Coral | C7: BR | D7: Branching hard coral | E7: MOSP | F7: Montipora sp | G7: MOBR | H7: Montipora branching | I7: *MOBR | J7: MOBR
A8: CORAL | B8: Coral | C8: BR | D8: Branching hard coral | E8: PLER | F8: Plerogyra sp | G8: PLER | H8: Plerogyra sp | I8: *PLER | J8: PLER
A9: CORAL | B9: Coral | C9: BR | D9: Branching hard coral | E9: POSP | F9: Porites sp | G9: POBR | H9: Porites branching | I9: *POBR | J9: POBR
A10: CORAL | B10: Coral | C10: BR | D10: Branching hard coral | E10: POCS | F10: Pocillopora sp | G10: POCS | H10: Pocillopora sp | I10: *POCS | J10: POCS
A11: CORAL | B11: Coral | C11: BR | D11: Branching hard coral | E11: STYS | F11: Stylophora sp | G11: STYS | H11: Stylophora sp | I11: *STYS | J11: STYS
A12: CORAL | B12: Coral | C12: COL | D12: Columnar hard coral | E12: COL | F12: Columnar hard coral | G12: COL | H12: Columnar hard coral | I12: *COL | J12: COL
... A111: UC | B111: Unclassified | C111: UNK | D111: Unclassified/Unknown | E111: UNK | F111: Unclassified/Unknown | G111: UNK | H111: Unclassified/Unknown | I111: *UNK | J111: UNK

Sheet All_BrokenDown
A1: Taxonomic Codes | B1: Taxonomic Desc | C1: Code Rank | D1: TF | F1: Structural Code | G1: Structural Desc | H1: Code Rank | J1: Hybrid Code | K1: Hybrid Desc | L1: Code Rank | N1: Substrate/Other
A2: CCA | B2: Coralline Alga | C2: T1 | D2: FALSE | F2: BR | G2: Branching hard coral | H2: T2 | J2: ACBR | K2: Acropora branching | L2: T3 | N2: TW | O2: Tape and wand | P2: T1 | Q2: TAPE | R2: Tape | S2: T2
A3: CORAL | B3: Coral | C3: T1 | D3: FALSE | F3: COL | G3: Columnar hard coral | H3: T2 | J3: ACTA | K3: Acropora tabulate | L3: T3 | N3: TW | O3: Tape and wand | P3: T1 | Q3: WAND | R3: Wand | S3: T2
A4: I | B4: Sessile Invertebrate | C4: T1 | D4: FALSE | F4: ENC | G4: Encrusting hard coral | H4: T2 | J4: MOBR | K4: Montipora branching | L4: T3 | N4: UC | O4: Unclassified | P4: T1
A5: MA | B5: Macroalga | C5: T1 | D5: FALSE | F5: FOL | G5: Foliose hard coral | H5: T2 | J5: MOEN | K5: Montipora encrusting | L5: T3 | N5: SED | O5: Sediment | P5: T1
A6: MF | B6: Mobile Fauna | C6: T1 | D6: FALSE | F6: FREE | G6: Free-living hard coral | H6: T2 | J6: MOFO | K6: Montipora foliose | L6: T3 | N6: SHAD | O6: Shadow | P6: T2
A7: SC | B7: Soft Coral | C7: T1 | D7: FALSE | F7: MASS | G7: Massive hard coral | H7: T2 | J7: MONE | K7: non-encrusting Montipora sp | L7: T3 | N7: UNK | O7: Unclassified/Unknown | P7: T2
A8: TURF | B8: Turf Alga | C8: T1 | D8: FALSE | F8: TAB | G8: Tabulate hard coral | H8: T2 | J8: PAEN | K8: Pavona encrusting | L8: T3 | N8: FINE | O8: Fine sediment | P8: T2
A9: AMNE | B9: Anemone | C9: T2 | D9: FALSE | J9: PAFO | K9: Pavona foliose | L9: T3 | N9: SAND | O9: Sand | P9: T2
A10: ANTI | B10: Wire and black coral | C10: T2 | D10: FALSE | J10: PAMA | K10: Pavona massive | L10: T3 | N10: HARD | O10: Hard substrate | P10: T2
A11: BI | B11: Bivalve | C11: T2 | D11: FALSE | J11: POBR | K11: Porites branching | L11: T3 | N11: RUB | O11: Rubble substrate | P11: T2
A12: BRY | B12: Bryozoan | C12: T2 | D12: FALSE | J12: POEN | K12: Porites encrusting | L12: T3
A13: CCAH | B13: CCA growing on hard substrate | C13: T2 | D13: FALSE | J13: POFO | K13: Porites foliose | L13: T3
A14: CCAR | B14: CCA growing on rubble | C14: T2 | D14: FALSE | J14: POMA | K14: Porites massive | L14: T3
A15: CMOR | B15: Corallimorph | C15: T2 | D15: FALSE | J15: PONM | K15: non-massive Porites sp | L15: T3
A16: EMA | B16: Encrusting macroalga | C16: T2 | D16: FALSE
A17: GC | B17: Giant clam | C17: T2 | D17: FALSE
A18: MOBF | B18: Mobile fauna | C18: T2 | D18: FALSE
A19: NS | B19: Non-scleractinian hard coral | C19: T2 | D19: FALSE
A20: OCTO | B20: Octocoral | C20: T2 | D20: FALSE
A21: SP | B21: Sponge | C21: T2 | D21: FALSE
A22: TUN | B22: Tunicate | C22: T2 | D22: FALSE
A23: TURFH | B23: Turf growing on hard substrate | C23: T2 | D23: FALSE
A24: TURFR | B24: Turf growing on rubble | C24: T2 | D24: FALSE
A25: UI | B25: Unclassified sessile invertebrate | C25: T2 | D25: FALSE
A26: UPMA | B26: Upright macroalga | C26: T2 | D26: FALSE
A27: USC | B27: Unclassified soft coral | C27: T2 | D27: FALSE
... A99: NEOM | B99: Neomeris sp | C99: T3 | D99: FALSE

Sheet BioticTaxonomic_CP
A1: Taxonomic Codes | B1: Taxonomic Desc | C1: Code Rank | D1: TF | F1: PARENT_CODE | G1: PARENT_DESC | H1: PARENT RANK | I1: CHILD_CODE | J1: CHILD_DESC | K1: CHILD_RANK
A2: CCA | B2: Coralline Alga | C2: T1 | D2: FALSE | F2: =_xlfn.XLOOKUP($I2,All_Photoquad_codes_HeirarchyTr!$G$2:$G$111,All_Photoquad_codes_HeirarchyTr!E$2:E$111) -> BRMA | G2: =_xlfn.XLOOKUP($I2,All_Photoquad_codes_HeirarchyTr!$G$2:$G$111,All_Photoquad_codes_HeirarchyTr!F$2:F$111) -> Brown macroalgae | H2: T2b | I2: DICO | J2: Dictyopteris/Dictyota | K2: T3
A3: CORAL | B3: Coral | C3: T1 | D3: FALSE | F3: CCA | G3: Coralline Alga | H3: T1 | I3: CCAH | J3: CCA growing on hard substrate | K3: T2
A4: I | B4: Sessile Invertebrate | C4: T1 | D4: FALSE | F4: CCA | G4: Coralline Alga | H4: T1 | I4: CCAR | J4: CCA growing on rubble | K4: T2
A5: MA | B5: Macroalga | C5: T1 | D5: FALSE | F5: CORAL | G5: Coral | H5: T1 | I5: NS | J5: Non-scleractinian hard coral | K5: T2
A6: MF | B6: Mobile Fauna | C6: T1 | D6: FALSE | F6: CORAL | G6: Coral | H6: T1 | I6: ACAS | J6: Acanthastrea sp | K6: T2b
A7: SC | B7: Soft Coral | C7: T1 | D7: FALSE | F7: =_xlfn.XLOOKUP($I7,All_Photoquad_codes_HeirarchyTr!$E$2:$E$111,All_Photoquad_codes_HeirarchyTr!A$2:A$111) -> CORAL | G7: =_xlfn.XLOOKUP($I7,All_Photoquad_codes_HeirarchyTr!$E$2:$E$111,All_Photoquad_codes_HeirarchyTr!B$2:B$111) -> Coral | H7: T1 | I7: ACSP | J7: Acropora sp | K7: T2b
A8: TURF | B8: Turf Alga | C8: T1 | D8: FALSE | F8: =_xlfn.XLOOKUP($I8,All_Photoquad_codes_HeirarchyTr!$E$2:$E$111,All_Photoquad_codes_HeirarchyTr!A$2:A$111) -> CORAL | G8: =_xlfn.XLOOKUP($I8,All_Photoquad_codes_HeirarchyTr!$E$2:$E$111,All_Photoquad_codes_HeirarchyTr!B$2:B$111) -> Coral | H8: T1 | I8: ASSP | J8: Astreopora sp | K8: T2b
A9: AMNE | B9: Anemone | C9: T2 | D9: FALSE | F9: =_xlfn.XLOOKUP($I9,All_Photoquad_codes_HeirarchyTr!$E$2:$E$111,All_Photoquad_codes_HeirarchyTr!A$2:A$111) -> CORAL | G9: =_xlfn.XLOOKUP($I9,All_Photoquad_codes_HeirarchyTr!$E$2:$E$111,All_Photoquad_codes_HeirarchyTr!B$2:B$111) -> Coral | H9: T1 | I9: ASTS | J9: Astrea spp | K9: T2b
A10: ANTI | B10: Wire and black coral | C10: T2 | D10: FALSE | F10: =_xlfn.XLOOKUP($I10,All_Photoquad_codes_HeirarchyTr!$E$2:$E$111,All_Photoquad_codes_HeirarchyTr!A$2:A$111) -> CORAL | G10: =_xlfn.XLOOKUP($I10,All_Photoquad_codes_HeirarchyTr!$E$2:$E$111,All_Photoquad_codes_HeirarchyTr!B$2:B$111) -> Coral | H10: T1 | I10: COSP | J10: Coscinaraea sp | K10: T2b
A11: BI | B11: Bivalve | C11: T2 | D11: FALSE | F11: =_xlfn.XLOOKUP($I11,All_Photoquad_codes_HeirarchyTr!$E$2:$E$111,All_Photoquad_codes_HeirarchyTr!A$2:A$111) -> CORAL | G11: =_xlfn.XLOOKUP($I11,All_Photoquad_codes_HeirarchyTr!$E$2:$E$111,All_Photoquad_codes_HeirarchyTr!B$2:B$111) -> Coral | H11: T1 | I11: CYPS | J11: Cyphastrea sp | K11: T2b
A12: BRY | B12: Bryozoan | C12: T2 | D12: FALSE | F12: =_xlfn.XLOOKUP($I12,All_Photoquad_codes_HeirarchyTr!$E$2:$E$111,All_Photoquad_codes_HeirarchyTr!A$2:A$111) -> CORAL | G12: =_xlfn.XLOOKUP($I12,All_Photoquad_codes_HeirarchyTr!$E$2:$E$111,All_Photoquad_codes_HeirarchyTr!B$2:B$111) -> Coral | H12: T1 | I12: DISP | J12: Diploastrea sp | K12: T2b | L12: ?
A13: CCAH | B13: CCA growing on hard substrate | C13: T2 | D13: FALSE | F13: =_xlfn.XLOOKUP($I13,All_Photoquad_codes_HeirarchyTr!$E$2:$E$111,All_Photoquad_codes_HeirarchyTr!A$2:A$111) -> CORAL | G13: =_xlfn.XLOOKUP($I13,All_Photoquad_codes_HeirarchyTr!$E$2:$E$111,All_Photoquad_codes_HeirarchyTr!B$2:B$111) -> Coral | H13: T1 | I13: ECHL | J13: Echinophyllia sp | K13: T2b
A14: CCAR | B14: CCA growing on rubble | C14: T2 | D14: FALSE | F14: =_xlfn.XLOOKUP($I14,All_Photoquad_codes_HeirarchyTr!$E$2:$E$111,All_Photoquad_codes_HeirarchyTr!A$2:A$111) -> CORAL | G14: =_xlfn.XLOOKUP($I14,All_Photoquad_codes_HeirarchyTr!$E$2:$E$111,All_Photoquad_codes_HeirarchyTr!B$2:B$111) -> Coral | H14: T1 | I14: ECHP | J14: Echinopora sp | K14: T2b
A15: CMOR | B15: Corallimorph | C15: T2 | D15: FALSE | F15: =_xlfn.XLOOKUP($I15,All_Photoquad_codes_HeirarchyTr!$E$2:$E$111,All_Photoquad_codes_HeirarchyTr!A$2:A$111) -> CORAL | G15: =_xlfn.XLOOKUP($I15,All_Photoquad_codes_HeirarchyTr!$E$2:$E$111,All_Photoquad_codes_HeirarchyTr!B$2:B$111) -> Coral | H15: T1 | I15: EUSP | J15: Euphyllia sp | K15: T2b
A16: EMA | B16: Encrusting macroalga | C16: T2 | D16: FALSE | F16: =_xlfn.XLOOKUP($I16,All_Photoquad_codes_HeirarchyTr!$E$2:$E$111,All_Photoquad_codes_HeirarchyTr!A$2:A$111) -> CORAL | G16: =_xlfn.XLOOKUP($I16,All_Photoquad_codes_HeirarchyTr!$E$2:$E$111,All_Photoquad_codes_HeirarchyTr!B$2:B$111) -> Coral | H16: T1 | I16: FASP | J16: Favia sp | K16: T2b
A17: GC | B17: Giant clam | C17: T2 | D17: FALSE | F17: =_xlfn.XLOOKUP($I17,All_Photoquad_codes_HeirarchyTr!$E$2:$E$111,All_Photoquad_codes_HeirarchyTr!A$2:A$111) -> CORAL | G17: =_xlfn.XLOOKUP($I17,All_Photoquad_codes_HeirarchyTr!$E$2:$E$111,All_Photoquad_codes_HeirarchyTr!B$2:B$111) -> Coral | H17: T1 | I17: FAVS | J17: Favites sp | K17: T2b
A18: MOBF | B18: Mobile fauna | C18: T2 | D18: FALSE | F18: =_xlfn.XLOOKUP($I18,All_Photoquad_codes_HeirarchyTr!$E$2:$E$111,All_Photoquad_codes_HeirarchyTr!A$2:A$111) -> CORAL | G18: =_xlfn.XLOOKUP($I18,All_Photoquad_codes_HeirarchyTr!$E$2:$E$111,All_Photoquad_codes_HeirarchyTr!B$2:B$111) -> Coral | H18: T1 | I18: FUSP | J18: Fungia sp | K18: T2b
A19: NS | B19: Non-scleractinian hard coral | C19: T2 | D19: FALSE | F19: =_xlfn.XLOOKUP($I19,All_Photoquad_codes_HeirarchyTr!$E$2:$E$111,All_Photoquad_codes_HeirarchyTr!A$2:A$111) -> CORAL | G19: =_xlfn.XLOOKUP($I19,All_Photoquad_codes_HeirarchyTr!$E$2:$E$111,All_Photoquad_codes_HeirarchyTr!B$2:B$111) -> Coral | H19: T1 | I19: GASP | J19: Galaxea sp | K19: T2b | L19: ?
A20: OCTO | B20: Octocoral | C20: T2 | D20: FALSE | F20: =_xlfn.XLOOKUP($I20,All_Photoquad_codes_HeirarchyTr!$E$2:$E$111,All_Photoquad_codes_HeirarchyTr!A$2:A$111) -> CORAL | G20: =_xlfn.XLOOKUP($I20,All_Photoquad_codes_HeirarchyTr!$E$2:$E$111,All_Photoquad_codes_HeirarchyTr!B$2:B$111) -> Coral | H20: T1 | I20: GOAL | J20: Goniopora/Alveopora sp | K20: T2b
A21: SP | B21: Sponge | C21: T2 | D21: FALSE | F21: =_xlfn.XLOOKUP($I21,All_Photoquad_codes_HeirarchyTr!$E$2:$E$111,All_Photoquad_codes_HeirarchyTr!A$2:A$111) -> CORAL | G21: =_xlfn.XLOOKUP($I21,All_Photoquad_codes_HeirarchyTr!$E$2:$E$111,All_Photoquad_codes_HeirarchyTr!B$2:B$111) -> Coral | H21: T1 | I21: GONS | J21: Goniastrea sp | K21: T2b | L21: ?
A22: TUN | B22: Tunicate | C22: T2 | D22: FALSE | F22: =_xlfn.XLOOKUP($I22,All_Photoquad_codes_HeirarchyTr!$E$2:$E$111,All_Photoquad_codes_HeirarchyTr!A$2:A$111) -> CORAL | G22: =_xlfn.XLOOKUP($I22,All_Photoquad_codes_HeirarchyTr!$E$2:$E$111,All_Photoquad_codes_HeirarchyTr!B$2:B$111) -> Coral | H22: T1 | I22: HCOE | J22: Heliopora sp | K22: T2b
A23: TURFH | B23: Turf growing on hard substrate | C23: T2 | D23: FALSE | F23: =_xlfn.XLOOKUP($I23,All_Photoquad_codes_HeirarchyTr!$E$2:$E$111,All_Photoquad_codes_HeirarchyTr!A$2:A$111) -> CORAL | G23: =_xlfn.XLOOKUP($I23,All_Photoquad_codes_HeirarchyTr!$E$2:$E$111,All_Photoquad_codes_HeirarchyTr!B$2:B$111) -> Coral | H23: T1 | I23: HYCO | J23: Hydrocoral | K23: T2b
A24: TURFR | B24: Turf growing on rubble | C24: T2 | D24: FALSE | F24: =_xlfn.XLOOKUP($I24,All_Photoquad_codes_HeirarchyTr!$E$2:$E$111,All_Photoquad_codes_HeirarchyTr!A$2:A$111) -> CORAL | G24: =_xlfn.XLOOKUP($I24,All_Photoquad_codes_HeirarchyTr!$E$2:$E$111,All_Photoquad_codes_HeirarchyTr!B$2:B$111) -> Coral | H24: T1 | I24: HYSP | J24: Hydnophora sp | K24: T2b
A25: UI | B25: Unclassified sessile invertebrate | C25: T2 | D25: FALSE | F25: =_xlfn.XLOOKUP($I25,All_Photoquad_codes_HeirarchyTr!$E$2:$E$111,All_Photoquad_codes_HeirarchyTr!A$2:A$111) -> CORAL | G25: =_xlfn.XLOOKUP($I25,All_Photoquad_codes_HeirarchyTr!$E$2:$E$111,All_Photoquad_codes_HeirarchyTr!B$2:B$111) -> Coral | H25: T1 | I25: ISSP | J25: Isopora sp | K25: T2b
A26: UPMA | B26: Upright macroalga | C26: T2 | D26: FALSE | F26: =_xlfn.XLOOKUP($I26,All_Photoquad_codes_HeirarchyTr!$E$2:$E$111,All_Photoquad_codes_HeirarchyTr!A$2:A$111) -> CORAL | G26: =_xlfn.XLOOKUP($I26,All_Photoquad_codes_HeirarchyTr!$E$2:$E$111,All_Photoquad_codes_HeirarchyTr!B$2:B$111) -> Coral | H26: T1 | I26: LEPT | J26: Leptastrea sp | K26: T2b
A27: USC | B27: Unclassified soft coral | C27: T2 | D27: FALSE | F27: =_xlfn.XLOOKUP($I27,All_Photoquad_codes_HeirarchyTr!$E$2:$E$111,All_Photoquad_codes_HeirarchyTr!A$2:A$111) -> CORAL | G27: =_xlfn.XLOOKUP($I27,All_Photoquad_codes_HeirarchyTr!$E$2:$E$111,All_Photoquad_codes_HeirarchyTr!B$2:B$111) -> Coral | H27: T1 | I27: LESP | J27: Leptoseris sp | K27: T2b
A28: ZO | B28: Zoanthid | C28: T2 | D28: FALSE | F28: =_xlfn.XLOOKUP($I28,All_Photoquad_codes_HeirarchyTr!$E$2:$E$111,All_Photoquad_codes_HeirarchyTr!A$2:A$111) -> CORAL | G28: =_xlfn.XLOOKUP($I28,All_Photoquad_codes_HeirarchyTr!$E$2:$E$111,All_Photoquad_codes_HeirarchyTr!B$2:B$111) -> Coral | H28: T1 | I28: LOBS | J28: Lobophyllia sp | K28: T2b
A29: ACAS | B29: Acanthastrea sp | C29: T2b | D29: FALSE | F29: =_xlfn.XLOOKUP($I29,All_Photoquad_codes_HeirarchyTr!$E$2:$E$111,All_Photoquad_codes_HeirarchyTr!A$2:A$111) -> CORAL | G29: =_xlfn.XLOOKUP($I29,All_Photoquad_codes_HeirarchyTr!$E$2:$E$111,All_Photoquad_codes_HeirarchyTr!B$2:B$111) -> Coral | H29: T1 | I29: LOSY | J29: Lobophyllia/Symphyllia sp | K29: T2b
A30: ACSP | B30: Acropora sp | C30: T2b | D30: FALSE | F30: =_xlfn.XLOOKUP($I30,All_Photoquad_codes_HeirarchyTr!$E$2:$E$111,All_Photoquad_codes_HeirarchyTr!A$2:A$111) -> CORAL | G30: =_xlfn.XLOOKUP($I30,All_Photoquad_codes_HeirarchyTr!$E$2:$E$111,All_Photoquad_codes_HeirarchyTr!B$2:B$111) -> Coral | H30: T1 | I30: LPHY | J30: Leptoria sp | K30: T2b
A31: ASPP | B31: Asparagopsis sp | C31: T2b | D31: FALSE | F31: =_xlfn.XLOOKUP($I31,All_Photoquad_codes_HeirarchyTr!$E$2:$E$111,All_Photoquad_codes_HeirarchyTr!A$2:A$111) -> CORAL | G31: =_xlfn.XLOOKUP($I31,All_Photoquad_codes_HeirarchyTr!$E$2:$E$111,All_Photoquad_codes_HeirarchyTr!B$2:B$111) -> Coral | H31: T1 | I31: MESP | J31: Merulina sp | K31: T2b
A32: ASSP | B32: Astreopora sp | C32: T2b | D32: FALSE | F32: =_xlfn.XLOOKUP($I32,All_Photoquad_codes_HeirarchyTr!$E$2:$E$111,All_Photoquad_codes_HeirarchyTr!A$2:A$111) -> CORAL | G32: =_xlfn.XLOOKUP($I32,All_Photoquad_codes_HeirarchyTr!$E$2:$E$111,All_Photoquad_codes_HeirarchyTr!B$2:B$111) -> Coral | H32: T1 | I32: MISP | J32: Millepora sp | K32: T2b
A33: ASTS | B33: Astrea spp | C33: T2b | D33: FALSE | F33: =_xlfn.XLOOKUP($I33,All_Photoquad_codes_HeirarchyTr!$E$2:$E$111,All_Photoquad_codes_HeirarchyTr!A$2:A$111) -> CORAL | G33: =_xlfn.XLOOKUP($I33,All_Photoquad_codes_HeirarchyTr!$E$2:$E$111,All_Photoquad_codes_HeirarchyTr!B$2:B$111) -> Coral | H33: T1 | I33: MONS | J33: Montastraea sp | K33: T2b
... A47: FUSP | B47: Fungia sp | C47: T2b | D47: FALSE | F47: =_xlfn.XLOOKUP($I47,All_Photoquad_codes_HeirarchyTr!$E$2:$E$111,All_Photoquad_codes_HeirarchyTr!A$2:A$111) -> CORAL | G47: =_xlfn.XLOOKUP($I47,All_Photoquad_codes_HeirarchyTr!$E$2:$E$111,All_Photoquad_codes_HeirarchyTr!B$2:B$111) -> Coral | H47: T1 | I47: TURS | J47: Turbinaria sp | K47: T2b
A48: GASP | B48: Galaxea sp | C48: T2b | D48: FALSE | F48: =_xlfn.XLOOKUP($I48,All_Photoquad_codes_HeirarchyTr!$G$2:$G$111,All_Photoquad_codes_HeirarchyTr!E$2:E$111) -> GRMA | G48: =_xlfn.XLOOKUP($I48,All_Photoquad_codes_HeirarchyTr!$G$2:$G$111,All_Photoquad_codes_HeirarchyTr!F$2:F$111) -> Green macroalga | H48: T2b | I48: AVSP | J48: Avrainvillea sp | K48: T3
A49: GOAL | B49: Goniopora/Alveopora sp | C49: T2b | D49: FALSE | F49: =_xlfn.XLOOKUP($I49,All_Photoquad_codes_HeirarchyTr!$G$2:$G$111,All_Photoquad_codes_HeirarchyTr!E$2:E$111) -> GRMA | G49: =_xlfn.XLOOKUP($I49,All_Photoquad_codes_HeirarchyTr!$G$2:$G$111,All_Photoquad_codes_HeirarchyTr!F$2:F$111) -> Green macroalgae | H49: T2b | I49: BOOD | J49: Boodlea sp | K49: T3
A50: GONS | B50: Goniastrea sp | C50: T2b | D50: FALSE | F50: =_xlfn.XLOOKUP($I50,All_Photoquad_codes_HeirarchyTr!$G$2:$G$111,All_Photoquad_codes_HeirarchyTr!E$2:E$111) -> GRMA | G50: =_xlfn.XLOOKUP($I50,All_Photoquad_codes_HeirarchyTr!$G$2:$G$111,All_Photoquad_codes_HeirarchyTr!F$2:F$111) -> Green macroalga | H50: T2b | I50: CAUL | J50: Caulerpa sp | K50: T3
A51: GRMA | B51: Green macroalga | C51: T2b | D51: FALSE | F51: =_xlfn.XLOOKUP($I51,All_Photoquad_codes_HeirarchyTr!$G$2:$G$111,All_Photoquad_codes_HeirarchyTr!E$2:E$111) -> GRMA | G51: =_xlfn.XLOOKUP($I51,All_Photoquad_codes_HeirarchyTr!$G$2:$G$111,All_Photoquad_codes_HeirarchyTr!F$2:F$111) -> Green macroalgae | H51: T2b | I51: CHLS | J51: Chlorodesmis sp | K51: T3
A52: HALI | B52: Halimeda sp | C52: T2b | D52: FALSE | F52: =_xlfn.XLOOKUP($I52,All_Photoquad_codes_HeirarchyTr!$G$2:$G$111,All_Photoquad_codes_HeirarchyTr!E$2:E$111) -> GRMA | G52: =_xlfn.XLOOKUP($I52,All_Photoquad_codes_HeirarchyTr!$G$2:$G$111,All_Photoquad_codes_HeirarchyTr!F$2:F$111) -> Green macroalgae | H52: T2b | I52: NEOM | J52: Neomeris sp | K52: T3
A53: HCOE | B53: Heliopora sp | C53: T2b | D53: FALSE | F53: I | G53: Sessile Invertebrate | H53: T1 | I53: AMNE | J53: Anemone | K53: T2
...

Sheet BioticTaxonomic
A1: Taxonomic Codes | B1: Taxonomic Desc | C1: Code Rank | D1: TF
A2: CCA | B2: Coralline Alga | C2: T1 | D2: FALSE
A3: CORAL | B3: Coral | C3: T1 | D3: FALSE
A4: I | B4: Sessile Invertebrate | C4: T1 | D4: FALSE
A5: MA | B5: Macroalga | C5: T1 | D5: FALSE
A6: MF | B6: Mobile Fauna | C6: T1 | D6: FALSE
A7: SC | B7: Soft Coral | C7: T1 | D7: FALSE
A8: TURF | B8: Turf Alga | C8: T1 | D8: FALSE
A9: AMNE | B9: Anemone | C9: T2 | D9: FALSE
A10: ANTI | B10: Wire and black coral | C10: T2 | D10: FALSE
A11: BI | B11: Bivalve | C11: T2 | D11: FALSE
A12: BRY | B12: Bryozoan | C12: T2 | D12: FALSE
A13: CCAH | B13: CCA growing on hard substrate | C13: T2 | D13: FALSE
... A99: NEOM | B99: Neomeris sp | C99: T3 | D99: FALSE

Sheet Abiotic
A1: TIER_2 | B1: T2_DESC | H1: Substrate/Other
A2: CCAH | B2: CCA growing on hard substrate | H2: TW | I2: Tape and wand | J2: T1 | K2: TAPE | L2: Tape | M2: T2
A3: CCAR | B3: CCA growing on rubble | K3: WAND | L3: Wand | M3: T2
A4: BR | B4: Branching hard coral | H4: UC | I4: Unclassified | J4: T1
A5: COL | B5: Columnar hard coral | H5: SED | I5: Sediment | J5: T1
A6: CORAL | B6: Hard coral | H6: SHAD | I6: Shadow | J6: T2
A7: ENC | B7: Encrusting hard coral | H7: UNK | I7: Unclassified/Unknown | J7: T2
A8: FOL | B8: Foliose hard coral | H8: FINE | I8: Fine sediment | J8: T2
A9: FREE | B9: Free-living hard coral | H9: SAND | I9: Sand | J9: T2
A10: MASS | B10: Massive hard coral | H10: HARD | I10: Hard substrate | J10: T2
A11: NS | B11: Non-scleractinian hard coral | H11: RUB | I11: Rubble substrate | J11: T2
A12: TAB | B12: Tabulate hard coral
A13: AMNE | B13: Anemone
A14: ANTI | B14: Wire and black coral
A15: BI | B15: Bivalve
A16: BRY | B16: Bryozoan
A17: CMOR | B17: Corallimorph
A18: GC | B18: Giant clam
A19: SP | B19: Sponge
A20: TUN | B20: Tunicate
A21: UI | B21: Unclassified sessile invertebrate
A22: ZO | B22: Zoanthid
A23: EMA | B23: Encrusting macroalga
... A33: TURFR | B33: Turf growing on rubble

Sheet Morphology
A1: Coral Morphology Code | B1: Coral Morphological Desc | C1: Code Rank
A2: BR | B2: Branching hard coral | C2: T2
A3: COL | B3: Columnar hard coral | C3: T2
A4: ENC | B4: Encrusting hard coral | C4: T2
A5: FOL | B5: Foliose hard coral | C5: T2
A6: FREE | B6: Free-living hard coral | C6: T2
A7: MASS | B7: Massive hard coral | C7: T2
A8: TAB | B8: Tabulate hard coral | C8: T2

Sheet TaxMorph
